29-Oct-25 19:15:58 | kmb - INFO - Start getting KMB stops
29-Oct-25 19:16:08 | kmb - ERROR - Other error occurred: HTTPSConnectionPool(host='data.etabus.gov.hk', port=443): Max retries exceeded with url: /v1/transport/kmb/stop (Caused by NameResolutionError("<urllib3.connection.HTTPSConnection object at 0x7f453bac0a50>: Failed to resolve 'data.etabus.gov.hk' ([Errno -3] Temporary failure in name resolution)"))
29-Oct-25 19:16:08 | kmb - ERROR - HTTPSConnectionPool(host='data.etabus.gov.hk', port=443): Max retries exceeded with url: /v1/transport/kmb/stop (Caused by NameResolutionError("<urllib3.connection.HTTPSConnection object at 0x7f453bac0a50>: Failed to resolve 'data.etabus.gov.hk' ([Errno -3] Temporary failure in name resolution)"))
Traceback (most recent call last):
  File "/opt/hostedtoolcache/Python/3.13.7/x64/lib/python3.13/site-packages/urllib3/connection.py", line 203, in _new_conn
    sock = connection.create_connection(
        (self._dns_host, self.port),
    ...<2 lines>...
        socket_options=self.socket_options,
    )
  File "/opt/hostedtoolcache/Python/3.13.7/x64/lib/python3.13/site-packages/urllib3/util/connection.py", line 60, in create_connection
    for res in socket.getaddrinfo(host, port, family, socket.SOCK_STREAM):
               ~~~~~~~~~~~~~~~~~~^^^^^^^^^^^^^^^^^^^^^^^^^^^^^^^^^^^^^^^^
  File "/opt/hostedtoolcache/Python/3.13.7/x64/lib/python3.13/socket.py", line 977, in getaddrinfo
    for res in _socket.getaddrinfo(host, port, family, type, proto, flags):
               ~~~~~~~~~~~~~~~~~~~^^^^^^^^^^^^^^^^^^^^^^^^^^^^^^^^^^^^^^^^
socket.gaierror: [Errno -3] Temporary failure in name resolution

The above exception was the direct cause of the following exception:

Traceback (most recent call last):
  File "/opt/hostedtoolcache/Python/3.13.7/x64/lib/python3.13/site-packages/urllib3/connectionpool.py", line 790, in urlopen
    response = self._make_request(
        conn,
    ...<10 lines>...
        **response_kw,
    )
  File "/opt/hostedtoolcache/Python/3.13.7/x64/lib/python3.13/site-packages/urllib3/connectionpool.py", line 491, in _make_request
    raise new_e
  File "/opt/hostedtoolcache/Python/3.13.7/x64/lib/python3.13/site-packages/urllib3/connectionpool.py", line 467, in _make_request
    self._validate_conn(conn)
    ~~~~~~~~~~~~~~~~~~~^^^^^^
  File "/opt/hostedtoolcache/Python/3.13.7/x64/lib/python3.13/site-packages/urllib3/connectionpool.py", line 1092, in _validate_conn
    conn.connect()
    ~~~~~~~~~~~~^^
  File "/opt/hostedtoolcache/Python/3.13.7/x64/lib/python3.13/site-packages/urllib3/connection.py", line 611, in connect
    self.sock = sock = self._new_conn()
                       ~~~~~~~~~~~~~~^^
  File "/opt/hostedtoolcache/Python/3.13.7/x64/lib/python3.13/site-packages/urllib3/connection.py", line 210, in _new_conn
    raise NameResolutionError(self.host, self, e) from e
urllib3.exceptions.NameResolutionError: <urllib3.connection.HTTPSConnection object at 0x7f453bac0a50>: Failed to resolve 'data.etabus.gov.hk' ([Errno -3] Temporary failure in name resolution)

The above exception was the direct cause of the following exception:

Traceback (most recent call last):
  File "/opt/hostedtoolcache/Python/3.13.7/x64/lib/python3.13/site-packages/requests/adapters.py", line 486, in send
    resp = conn.urlopen(
        method=request.method,
    ...<9 lines>...
        chunked=chunked,
    )
  File "/opt/hostedtoolcache/Python/3.13.7/x64/lib/python3.13/site-packages/urllib3/connectionpool.py", line 844, in urlopen
    retries = retries.increment(
        method, url, error=new_e, _pool=self, _stacktrace=sys.exc_info()[2]
    )
  File "/opt/hostedtoolcache/Python/3.13.7/x64/lib/python3.13/site-packages/urllib3/util/retry.py", line 515, in increment
    raise MaxRetryError(_pool, url, reason) from reason  # type: ignore[arg-type]
    ^^^^^^^^^^^^^^^^^^^^^^^^^^^^^^^^^^^^^^^^^^^^^^^^^^^
urllib3.exceptions.MaxRetryError: HTTPSConnectionPool(host='data.etabus.gov.hk', port=443): Max retries exceeded with url: /v1/transport/kmb/stop (Caused by NameResolutionError("<urllib3.connection.HTTPSConnection object at 0x7f453bac0a50>: Failed to resolve 'data.etabus.gov.hk' ([Errno -3] Temporary failure in name resolution)"))

During handling of the above exception, another exception occurred:

Traceback (most recent call last):
  File "/home/runner/work/BusData/BusData/action/KMB_Route.py", line 76, in main
    allStopResponse = requests.get(allStopBaseUrl, timeout=30.0)
  File "/opt/hostedtoolcache/Python/3.13.7/x64/lib/python3.13/site-packages/requests/api.py", line 73, in get
    return request("get", url, params=params, **kwargs)
  File "/opt/hostedtoolcache/Python/3.13.7/x64/lib/python3.13/site-packages/requests/api.py", line 59, in request
    return session.request(method=method, url=url, **kwargs)
           ~~~~~~~~~~~~~~~^^^^^^^^^^^^^^^^^^^^^^^^^^^^^^^^^^
  File "/opt/hostedtoolcache/Python/3.13.7/x64/lib/python3.13/site-packages/requests/sessions.py", line 589, in request
    resp = self.send(prep, **send_kwargs)
  File "/opt/hostedtoolcache/Python/3.13.7/x64/lib/python3.13/site-packages/requests/sessions.py", line 703, in send
    r = adapter.send(request, **kwargs)
  File "/opt/hostedtoolcache/Python/3.13.7/x64/lib/python3.13/site-packages/requests/adapters.py", line 519, in send
    raise ConnectionError(e, request=request)
requests.exceptions.ConnectionError: HTTPSConnectionPool(host='data.etabus.gov.hk', port=443): Max retries exceeded with url: /v1/transport/kmb/stop (Caused by NameResolutionError("<urllib3.connection.HTTPSConnection object at 0x7f453bac0a50>: Failed to resolve 'data.etabus.gov.hk' ([Errno -3] Temporary failure in name resolution)"))
