15-Sep-25 19:15:14 | kmb - INFO - Start getting KMB stops
15-Sep-25 19:15:44 | kmb - ERROR - Other error occurred: HTTPSConnectionPool(host='data.etabus.gov.hk', port=443): Read timed out. (read timeout=30.0)
15-Sep-25 19:15:44 | kmb - ERROR - HTTPSConnectionPool(host='data.etabus.gov.hk', port=443): Read timed out. (read timeout=30.0)
Traceback (most recent call last):
  File "/opt/hostedtoolcache/Python/3.13.7/x64/lib/python3.13/site-packages/urllib3/connectionpool.py", line 536, in _make_request
    response = conn.getresponse()
  File "/opt/hostedtoolcache/Python/3.13.7/x64/lib/python3.13/site-packages/urllib3/connection.py", line 461, in getresponse
    httplib_response = super().getresponse()
  File "/opt/hostedtoolcache/Python/3.13.7/x64/lib/python3.13/http/client.py", line 1430, in getresponse
    response.begin()
    ~~~~~~~~~~~~~~^^
  File "/opt/hostedtoolcache/Python/3.13.7/x64/lib/python3.13/http/client.py", line 331, in begin
    version, status, reason = self._read_status()
                              ~~~~~~~~~~~~~~~~~^^
  File "/opt/hostedtoolcache/Python/3.13.7/x64/lib/python3.13/http/client.py", line 292, in _read_status
    line = str(self.fp.readline(_MAXLINE + 1), "iso-8859-1")
               ~~~~~~~~~~~~~~~~^^^^^^^^^^^^^^
  File "/opt/hostedtoolcache/Python/3.13.7/x64/lib/python3.13/socket.py", line 719, in readinto
    return self._sock.recv_into(b)
           ~~~~~~~~~~~~~~~~~~~~^^^
  File "/opt/hostedtoolcache/Python/3.13.7/x64/lib/python3.13/ssl.py", line 1304, in recv_into
    return self.read(nbytes, buffer)
           ~~~~~~~~~^^^^^^^^^^^^^^^^
  File "/opt/hostedtoolcache/Python/3.13.7/x64/lib/python3.13/ssl.py", line 1138, in read
    return self._sslobj.read(len, buffer)
           ~~~~~~~~~~~~~~~~~^^^^^^^^^^^^^
TimeoutError: The read operation timed out

The above exception was the direct cause of the following exception:

Traceback (most recent call last):
  File "/opt/hostedtoolcache/Python/3.13.7/x64/lib/python3.13/site-packages/requests/adapters.py", line 486, in send
    resp = conn.urlopen(
        method=request.method,
    ...<9 lines>...
        chunked=chunked,
    )
  File "/opt/hostedtoolcache/Python/3.13.7/x64/lib/python3.13/site-packages/urllib3/connectionpool.py", line 844, in urlopen
    retries = retries.increment(
        method, url, error=new_e, _pool=self, _stacktrace=sys.exc_info()[2]
    )
  File "/opt/hostedtoolcache/Python/3.13.7/x64/lib/python3.13/site-packages/urllib3/util/retry.py", line 470, in increment
    raise reraise(type(error), error, _stacktrace)
          ~~~~~~~^^^^^^^^^^^^^^^^^^^^^^^^^^^^^^^^^
  File "/opt/hostedtoolcache/Python/3.13.7/x64/lib/python3.13/site-packages/urllib3/util/util.py", line 39, in reraise
    raise value
  File "/opt/hostedtoolcache/Python/3.13.7/x64/lib/python3.13/site-packages/urllib3/connectionpool.py", line 790, in urlopen
    response = self._make_request(
        conn,
    ...<10 lines>...
        **response_kw,
    )
  File "/opt/hostedtoolcache/Python/3.13.7/x64/lib/python3.13/site-packages/urllib3/connectionpool.py", line 538, in _make_request
    self._raise_timeout(err=e, url=url, timeout_value=read_timeout)
    ~~~~~~~~~~~~~~~~~~~^^^^^^^^^^^^^^^^^^^^^^^^^^^^^^^^^^^^^^^^^^^^
  File "/opt/hostedtoolcache/Python/3.13.7/x64/lib/python3.13/site-packages/urllib3/connectionpool.py", line 370, in _raise_timeout
    raise ReadTimeoutError(
        self, url, f"Read timed out. (read timeout={timeout_value})"
    ) from err
urllib3.exceptions.ReadTimeoutError: HTTPSConnectionPool(host='data.etabus.gov.hk', port=443): Read timed out. (read timeout=30.0)

During handling of the above exception, another exception occurred:

Traceback (most recent call last):
  File "/home/runner/work/BusData/BusData/action/KMB_Route.py", line 76, in main
    allStopResponse = requests.get(allStopBaseUrl, timeout=30.0)
  File "/opt/hostedtoolcache/Python/3.13.7/x64/lib/python3.13/site-packages/requests/api.py", line 73, in get
    return request("get", url, params=params, **kwargs)
  File "/opt/hostedtoolcache/Python/3.13.7/x64/lib/python3.13/site-packages/requests/api.py", line 59, in request
    return session.request(method=method, url=url, **kwargs)
           ~~~~~~~~~~~~~~~^^^^^^^^^^^^^^^^^^^^^^^^^^^^^^^^^^
  File "/opt/hostedtoolcache/Python/3.13.7/x64/lib/python3.13/site-packages/requests/sessions.py", line 589, in request
    resp = self.send(prep, **send_kwargs)
  File "/opt/hostedtoolcache/Python/3.13.7/x64/lib/python3.13/site-packages/requests/sessions.py", line 703, in send
    r = adapter.send(request, **kwargs)
  File "/opt/hostedtoolcache/Python/3.13.7/x64/lib/python3.13/site-packages/requests/adapters.py", line 532, in send
    raise ReadTimeout(e, request=request)
requests.exceptions.ReadTimeout: HTTPSConnectionPool(host='data.etabus.gov.hk', port=443): Read timed out. (read timeout=30.0)
