18-Oct-23 19:07:34 | root - INFO - Start getting NLB routes
18-Oct-23 19:07:38 | httpx - INFO - HTTP Request: GET https://rt.data.gov.hk/v2/transport/nlb/stop.php?action=list&routeId=9 "HTTP/1.1 200 OK"
18-Oct-23 19:07:39 | httpx - INFO - HTTP Request: GET https://rt.data.gov.hk/v2/transport/nlb/stop.php?action=list&routeId=24 "HTTP/1.1 200 OK"
18-Oct-23 19:07:43 | root - ERROR - Other error occurred: 
18-Oct-23 19:07:43 | root - ERROR - 
Traceback (most recent call last):
  File "/opt/hostedtoolcache/Python/3.11.6/x64/lib/python3.11/site-packages/anyio/streams/tls.py", line 131, in _call_sslobject_method
    result = func(*args)
             ^^^^^^^^^^^
  File "/opt/hostedtoolcache/Python/3.11.6/x64/lib/python3.11/ssl.py", line 921, in read
    v = self._sslobj.read(len)
        ^^^^^^^^^^^^^^^^^^^^^^
ssl.SSLWantReadError: The operation did not complete (read) (_ssl.c:2580)

During handling of the above exception, another exception occurred:

Traceback (most recent call last):
  File "/opt/hostedtoolcache/Python/3.11.6/x64/lib/python3.11/site-packages/httpcore/_backends/anyio.py", line 34, in read
    return await self._stream.receive(max_bytes=max_bytes)
           ^^^^^^^^^^^^^^^^^^^^^^^^^^^^^^^^^^^^^^^^^^^^^^^
  File "/opt/hostedtoolcache/Python/3.11.6/x64/lib/python3.11/site-packages/anyio/streams/tls.py", line 196, in receive
    data = await self._call_sslobject_method(self._ssl_object.read, max_bytes)
           ^^^^^^^^^^^^^^^^^^^^^^^^^^^^^^^^^^^^^^^^^^^^^^^^^^^^^^^^^^^^^^^^^^^
  File "/opt/hostedtoolcache/Python/3.11.6/x64/lib/python3.11/site-packages/anyio/streams/tls.py", line 138, in _call_sslobject_method
    data = await self.transport_stream.receive()
           ^^^^^^^^^^^^^^^^^^^^^^^^^^^^^^^^^^^^^
  File "/opt/hostedtoolcache/Python/3.11.6/x64/lib/python3.11/site-packages/anyio/_backends/_asyncio.py", line 1203, in receive
    await self._protocol.read_event.wait()
  File "/opt/hostedtoolcache/Python/3.11.6/x64/lib/python3.11/asyncio/locks.py", line 213, in wait
    await fut
asyncio.exceptions.CancelledError

During handling of the above exception, another exception occurred:

Traceback (most recent call last):
  File "/opt/hostedtoolcache/Python/3.11.6/x64/lib/python3.11/site-packages/httpcore/_exceptions.py", line 10, in map_exceptions
    yield
  File "/opt/hostedtoolcache/Python/3.11.6/x64/lib/python3.11/site-packages/httpcore/_backends/anyio.py", line 32, in read
    with anyio.fail_after(timeout):
  File "/opt/hostedtoolcache/Python/3.11.6/x64/lib/python3.11/site-packages/anyio/_core/_tasks.py", line 119, in __exit__
    raise TimeoutError
TimeoutError

The above exception was the direct cause of the following exception:

Traceback (most recent call last):
  File "/opt/hostedtoolcache/Python/3.11.6/x64/lib/python3.11/site-packages/httpx/_transports/default.py", line 60, in map_httpcore_exceptions
    yield
  File "/opt/hostedtoolcache/Python/3.11.6/x64/lib/python3.11/site-packages/httpx/_transports/default.py", line 353, in handle_async_request
    resp = await self._pool.handle_async_request(req)
           ^^^^^^^^^^^^^^^^^^^^^^^^^^^^^^^^^^^^^^^^^^
  File "/opt/hostedtoolcache/Python/3.11.6/x64/lib/python3.11/site-packages/httpcore/_async/connection_pool.py", line 262, in handle_async_request
    raise exc
  File "/opt/hostedtoolcache/Python/3.11.6/x64/lib/python3.11/site-packages/httpcore/_async/connection_pool.py", line 245, in handle_async_request
    response = await connection.handle_async_request(request)
               ^^^^^^^^^^^^^^^^^^^^^^^^^^^^^^^^^^^^^^^^^^^^^^
  File "/opt/hostedtoolcache/Python/3.11.6/x64/lib/python3.11/site-packages/httpcore/_async/connection.py", line 96, in handle_async_request
    return await self._connection.handle_async_request(request)
           ^^^^^^^^^^^^^^^^^^^^^^^^^^^^^^^^^^^^^^^^^^^^^^^^^^^^
  File "/opt/hostedtoolcache/Python/3.11.6/x64/lib/python3.11/site-packages/httpcore/_async/http11.py", line 121, in handle_async_request
    raise exc
  File "/opt/hostedtoolcache/Python/3.11.6/x64/lib/python3.11/site-packages/httpcore/_async/http11.py", line 99, in handle_async_request
    ) = await self._receive_response_headers(**kwargs)
        ^^^^^^^^^^^^^^^^^^^^^^^^^^^^^^^^^^^^^^^^^^^^^^
  File "/opt/hostedtoolcache/Python/3.11.6/x64/lib/python3.11/site-packages/httpcore/_async/http11.py", line 164, in _receive_response_headers
    event = await self._receive_event(timeout=timeout)
            ^^^^^^^^^^^^^^^^^^^^^^^^^^^^^^^^^^^^^^^^^^
  File "/opt/hostedtoolcache/Python/3.11.6/x64/lib/python3.11/site-packages/httpcore/_async/http11.py", line 200, in _receive_event
    data = await self._network_stream.read(
           ^^^^^^^^^^^^^^^^^^^^^^^^^^^^^^^^
  File "/opt/hostedtoolcache/Python/3.11.6/x64/lib/python3.11/site-packages/httpcore/_backends/anyio.py", line 31, in read
    with map_exceptions(exc_map):
  File "/opt/hostedtoolcache/Python/3.11.6/x64/lib/python3.11/contextlib.py", line 155, in __exit__
    self.gen.throw(typ, value, traceback)
  File "/opt/hostedtoolcache/Python/3.11.6/x64/lib/python3.11/site-packages/httpcore/_exceptions.py", line 14, in map_exceptions
    raise to_exc(exc) from exc
httpcore.ReadTimeout

The above exception was the direct cause of the following exception:

Traceback (most recent call last):
  File "/home/runner/work/BusData/BusData/action/NLB_Route.py", line 116, in main
    nlbList += await asyncio.gather(*tasks)
               ^^^^^^^^^^^^^^^^^^^^^^^^^^^^
  File "/home/runner/work/BusData/BusData/action/NLB_Route.py", line 46, in getStopList
    stopListResponse = await client.get(stopListUrl)
                       ^^^^^^^^^^^^^^^^^^^^^^^^^^^^^
  File "/opt/hostedtoolcache/Python/3.11.6/x64/lib/python3.11/site-packages/httpx/_client.py", line 1757, in get
    return await self.request(
           ^^^^^^^^^^^^^^^^^^^
  File "/opt/hostedtoolcache/Python/3.11.6/x64/lib/python3.11/site-packages/httpx/_client.py", line 1530, in request
    return await self.send(request, auth=auth, follow_redirects=follow_redirects)
           ^^^^^^^^^^^^^^^^^^^^^^^^^^^^^^^^^^^^^^^^^^^^^^^^^^^^^^^^^^^^^^^^^^^^^^
  File "/opt/hostedtoolcache/Python/3.11.6/x64/lib/python3.11/site-packages/httpx/_client.py", line 1617, in send
    response = await self._send_handling_auth(
               ^^^^^^^^^^^^^^^^^^^^^^^^^^^^^^^
  File "/opt/hostedtoolcache/Python/3.11.6/x64/lib/python3.11/site-packages/httpx/_client.py", line 1645, in _send_handling_auth
    response = await self._send_handling_redirects(
               ^^^^^^^^^^^^^^^^^^^^^^^^^^^^^^^^^^^^
  File "/opt/hostedtoolcache/Python/3.11.6/x64/lib/python3.11/site-packages/httpx/_client.py", line 1682, in _send_handling_redirects
    response = await self._send_single_request(request)
               ^^^^^^^^^^^^^^^^^^^^^^^^^^^^^^^^^^^^^^^^
  File "/opt/hostedtoolcache/Python/3.11.6/x64/lib/python3.11/site-packages/httpx/_client.py", line 1719, in _send_single_request
    response = await transport.handle_async_request(request)
               ^^^^^^^^^^^^^^^^^^^^^^^^^^^^^^^^^^^^^^^^^^^^^
  File "/opt/hostedtoolcache/Python/3.11.6/x64/lib/python3.11/site-packages/httpx/_transports/default.py", line 352, in handle_async_request
    with map_httpcore_exceptions():
  File "/opt/hostedtoolcache/Python/3.11.6/x64/lib/python3.11/contextlib.py", line 155, in __exit__
    self.gen.throw(typ, value, traceback)
  File "/opt/hostedtoolcache/Python/3.11.6/x64/lib/python3.11/site-packages/httpx/_transports/default.py", line 77, in map_httpcore_exceptions
    raise mapped_exc(message) from exc
httpx.ReadTimeout
